{
  "chunk_id": "chunk-complex-001",
  "chunk_seq": 0,
  "events": [
    {
      "id": "evt-001",
      "seq": 0,
      "ts_client_s": 1696440000.0,
      "ts_server_s": 1696440000.0,
      "type": "rationale_note",
      "structured": {
        "plan": "User reports that API returns 500 error when creating orders with multiple items",
        "hypothesis": "Likely a database constraint violation or validation issue in order processing",
        "next_step": "First, check the error logs to understand the actual error"
      }
    },
    {
      "id": "evt-002",
      "seq": 1,
      "ts_client_s": 1696440010.0,
      "ts_server_s": 1696440010.0,
      "type": "cmd_run",
      "cmd": "grep -r \"500 Internal Server Error\" logs/api.log | tail -20",
      "cwd": "/workspace",
      "exit_code": 0,
      "env_redacted": false
    },
    {
      "id": "evt-003",
      "seq": 2,
      "ts_client_s": 1696440020.0,
      "ts_server_s": 1696440020.0,
      "type": "rationale_note",
      "structured": {
        "observation": "Error shows: 'list index out of range' in calculate_order_total function",
        "hypothesis": "The function assumes at least one item but doesn't validate empty items list",
        "next_step": "Run the failing test to reproduce the issue"
      }
    },
    {
      "id": "evt-004",
      "seq": 3,
      "ts_client_s": 1696440030.0,
      "ts_server_s": 1696440030.0,
      "type": "cmd_run",
      "cmd": "pytest tests/test_orders.py::test_create_order_with_multiple_items -v",
      "cwd": "/workspace",
      "exit_code": 1,
      "env_redacted": false
    },
    {
      "id": "evt-005",
      "seq": 4,
      "ts_client_s": 1696440040.0,
      "ts_server_s": 1696440040.0,
      "type": "test_run",
      "framework": "pytest",
      "selection": "tests/test_orders.py::test_create_order_with_multiple_items",
      "num_passed": 0,
      "num_failed": 1,
      "failed_tests": ["test_create_order_with_multiple_items"]
    }
  ],
  "artifacts": {
    "stdout_evt_002": {
      "type": "stdout",
      "event_id": "evt-002",
      "content": "[ERROR] OrderService.calculate_total - IndexError: list index out of range\n[ERROR] Traceback: File 'services/order_service.py', line 42\n[ERROR] Failed to process order for user_id=123"
    },
    "stdout_evt_004": {
      "type": "stdout",
      "event_id": "evt-004",
      "content": "============================= test session starts ==============================\ntests/test_orders.py::test_create_order_with_multiple_items FAILED      [100%]\n\n=================================== FAILURES ===================================\n______________________ test_create_order_with_multiple_items ___________________\n\n    def test_create_order_with_multiple_items():\n        items = [{\"product_id\": 1, \"quantity\": 2}, {\"product_id\": 2, \"quantity\": 1}]\n>       order = create_order(user_id=123, items=items)\nE       IndexError: list index out of range\n\nFile services/order_service.py, line 42, in calculate_order_total\n    first_item_price = item_prices[0]\nIndexError: list index out of range"
    }
  }
}

